<?xml version="1.0" encoding="utf-8"?>
<!-- =================================================================================== -->
<!-- |    This document was autogenerated by xacro from talos_lower_body.urdf.xacro    | -->
<!-- |    EDITING THIS FILE BY HAND IS NOT RECOMMENDED                                 | -->
<!-- =================================================================================== -->
<!--

  Copyright (c) 2016, PAL Robotics, S.L.
  All rights reserved.

  This work is licensed under the Creative Commons Attribution-NonCommercial-NoDerivs 3.0 Unported License.
  To view a copy of this license, visit http://creativecommons.org/licenses/by-nc-nd/3.0/ or send a letter to
  Creative Commons, 444 Castro Street, Suite 900, Mountain View, California, 94041, USA.
-->
<robot name="talos" xmlns:controller="http://playerstage.sourceforge.net/gazebo/xmlschema/#controller" xmlns:interface="http://playerstage.sourceforge.net/gazebo/xmlschema/#interface" xmlns:sensor="http://playerstage.sourceforge.net/gazebo/xmlschema/#sensor">
  <!--************************-->
  <!--        BASE_LINK       -->
  <!--************************-->
  <link name="base_link">
    <inertial>
      <origin rpy="0.00000 0.00000 0.00000" xyz="-0.08222 0.00838 -0.07261"/>
      <mass value="13.53810"/>
      <inertia ixx="0.06989000000" ixy="-0.00011700000" ixz="0.00023000000" iyy="0.03998200000" iyz="-0.00132500000" izz="0.08234500000"/>
    </inertial>
    <visual>
      <origin rpy="0 0 0" xyz="0 0 0"/>
      <geometry>
        <mesh filename="package://talos_description/meshes/torso/base_link.STL" scale="1 1 1"/>
      </geometry>
      <material name="LightGrey"/>
    </visual>
    <collision>
      <origin rpy="0 0 0" xyz="0 0 0"/>
      <geometry>
        <mesh filename="package://talos_description/meshes/torso/base_link_collision.STL" scale="1 1 1"/>
      </geometry>
    </collision>
  </link>
  <!-- Joint hip_z (mesh link) : child link hip_x -> parent link base_link -->
  <link name="leg_left_1_link">
    <inertial>
      <mass value="1.845591"/>
      <inertia ixx="0.00541533521" ixy="-0.00015428714" ixz="0.00131612622" iyy="0.00848624936" iyz="-1.906103e-05" izz="0.00474512541"/>
      <origin rpy="0 0 0" xyz="0.02247868 0.00106736 0.03130665"/>
    </inertial>
    <visual>
      <origin rpy="0 0 0" xyz="0 0 0"/>
      <geometry>
        <mesh filename="package://talos_description/meshes/v2/hip_z_lo_res.stl" scale="1 1 1"/>
      </geometry>
      <material name="DarkGrey"/>
    </visual>
    <collision>
      <origin rpy="0 0 0" xyz="0 0 0"/>
      <geometry>
        <mesh filename="package://talos_description/meshes/v2/hip_z_collision.stl" scale="1 1 1"/>
      </geometry>
    </collision>
  </link>
  <joint name="leg_left_1_joint" type="revolute">
    <parent link="base_link"/>
    <child link="leg_left_1_link"/>
    <origin rpy="0.0 0.0 0.0" xyz="-0.02 0.085 -0.27105"/>
    <axis xyz="0 0 1"/>
    <limit effort="100" lower="-0.349065850399" upper="1.57079632679" velocity="3.87"/>
    <dynamics damping="0.0" friction="0.0"/>
  </joint>
  <!-- Joint hip_x (mesh link) : child link hip_y -> parent link hip_z -->
  <link name="leg_left_2_link">
    <inertial>
      <mass value="1.490952"/>
      <inertia ixx="0.00497152259" ixy="-0.0001311358" ixz="-4.86648e-06" iyy="0.00190550993" iyz="4.585381e-05" izz="0.00474289754"/>
      <origin rpy="0 0 0" xyz="-0.00704703 0.02592659 0.00273385"/>
    </inertial>
    <visual>
      <origin rpy="0  0  0" xyz="0 0 0.0"/>
      <geometry>
        <mesh filename="package://talos_description/meshes/v2/hip_x_lo_res.stl" scale="1 1 1"/>
      </geometry>
      <material name="DarkGrey"/>
    </visual>
    <collision>
      <origin rpy="0  0  0" xyz="0 0 0.0"/>
      <geometry>
        <mesh filename="package://talos_description/meshes/v2/hip_x_collision.stl" scale="1 1 1"/>
      </geometry>
    </collision>
  </link>
  <joint name="leg_left_2_joint" type="revolute">
    <parent link="leg_left_1_link"/>
    <child link="leg_left_2_link"/>
    <origin rpy="0.0 0.0 0.0" xyz="0.00000 0.00000 0.00000"/>
    <axis xyz="1 0 0"/>
    <limit effort="160" lower="-0.5236" upper="0.5236" velocity="5.8"/>
    <dynamics damping="0.0" friction="0.0"/>
  </joint>
  <!-- Joint hip_y (mesh link) : child link knee -> parent link hip_x -->
  <link name="leg_left_3_link">
    <inertial>
      <mass value="6.239871"/>
      <inertia ixx="0.15337403915" ixy="0.00068913396" ixz="0.00168034366" iyy="0.13648139346" iyz="-0.02187635445" izz="0.03001594885"/>
      <origin rpy="0 0 0" xyz="0.0058523 0.0636967 -0.18339564"/>
    </inertial>
    <visual>
      <origin rpy="0 0 0" xyz="0 0 0"/>
      <geometry>
        <mesh filename="package://talos_description/meshes/v2/hip_y_lo_res.stl" scale="1 1 1"/>
      </geometry>
      <material name="DarkGrey"/>
    </visual>
    <collision>
      <origin rpy="0 0 0" xyz="0 0 0"/>
      <geometry>
        <mesh filename="package://talos_description/meshes/v2/hip_y_collision.stl" scale="1 1 1"/>
      </geometry>
    </collision>
  </link>
  <joint name="leg_left_3_joint" type="revolute">
    <parent link="leg_left_2_link"/>
    <child link="leg_left_3_link"/>
    <origin rpy="0.0 0.0 0.0" xyz="0.00000 0.00000 0.00000"/>
    <axis xyz="0 1 0"/>
    <limit effort="160" lower="-2.095" upper="0.7" velocity="5.8"/>
    <dynamics damping="0.0" friction="0.0"/>
  </joint>
  <!-- Joint knee (mesh link) : child link ankle_y -> parent link hip_y -->
  <link name="leg_left_4_link">
    <inertial>
      <mass value="3.759951"/>
      <inertia ixx="0.04287677484" ixy="0.00043705397" ixz="0.00078292368" iyy="0.03598906971" iyz="0.00037717694" izz="0.01364791564"/>
      <origin rpy="0 0 0" xyz="0.01317717 0.02917508 -0.11594602"/>
    </inertial>
    <visual>
      <origin rpy="0 0 0" xyz="0 0 0"/>
      <geometry>
        <mesh filename="package://talos_description/meshes/v2/knee_lo_res.stl" scale="1 1 1"/>
      </geometry>
      <material name="DarkGrey"/>
    </visual>
    <collision>
      <origin rpy="0 0 0" xyz="0 0 0"/>
      <geometry>
        <mesh filename="package://talos_description/meshes/v2/knee_collision.stl" scale="1 1 1"/>
      </geometry>
    </collision>
  </link>
  <joint name="leg_left_4_joint" type="revolute">
    <parent link="leg_left_3_link"/>
    <child link="leg_left_4_link"/>
    <origin rpy="0.0 0.0 0.0" xyz="0.00000 0.00000 -0.38000"/>
    <axis xyz="0 1 0"/>
    <limit effort="400" lower="0" upper="2.618" velocity="7"/>
    <dynamics damping="0.0" friction="0.0"/>
  </joint>
  <!-- Joint ankle_y (mesh link) : child link ankle_x -> parent link knee -->
  <link name="leg_left_5_link">
    <inertial>
      <mass value="1.29096"/>
      <inertia ixx="0.01143430819" ixy="0.00096978273" ixz="0.00039976581" iyy="0.00888974312" iyz="-0.00277808667" izz="0.00506373875"/>
      <origin rpy="0 0 0" xyz="-0.01400838 0.04180064 0.03820186"/>
    </inertial>
    <visual>
      <origin rpy="0 0 0" xyz="0 0 0.0"/>
      <geometry>
        <mesh filename="package://talos_description/meshes/v2/ankle_Y_lo_res.stl" scale="1 1 1"/>
      </geometry>
      <material name="Grey"/>
    </visual>
    <collision>
      <origin rpy="0 0 0" xyz="0 0 0.0"/>
      <geometry>
        <mesh filename="package://talos_description/meshes/v2/ankle_Y_collision.stl" scale="1 1 1"/>
      </geometry>
    </collision>
  </link>
  <joint name="leg_left_5_joint" type="revolute">
    <parent link="leg_left_4_link"/>
    <child link="leg_left_5_link"/>
    <origin rpy="0.0 0.0 0.0" xyz="0.00000 0.00000 -0.32500"/>
    <axis xyz="0 1 0"/>
    <limit effort="160" lower="-1.27" upper="0.68" velocity="5.8"/>
    <dynamics damping="0.0" friction="0.0"/>
  </joint>
  <!-- Joint ankle_x (mesh link) : child link None -> parent link ankle_y -->
  <link name="leg_left_6_link">
    <inertial>
      <mass value="1.597773"/>
      <inertia ixx="0.00439027267" ixy="-6.743674e-05" ixz="0.00113816363" iyy="0.00743063029" iyz="3.943143e-05" izz="0.00550906699"/>
      <origin rpy="0 0 0" xyz="-0.02034668 -0.00051514 -0.05987428"/>
    </inertial>
    <visual>
      <origin rpy="0 0 0" xyz="0 0 0"/>
      <geometry>
        <mesh filename="package://talos_description/meshes/v2/ankle_X_lo_res.stl" scale="1 1 1"/>
      </geometry>
      <material name="Grey"/>
    </visual>
    <collision>
      <origin rpy="0 0 0" xyz="0 0 0"/>
      <geometry>
        <mesh filename="package://talos_description/meshes/v2/ankle_X_collision.stl" scale="1 1 1"/>
      </geometry>
    </collision>
  </link>
  <joint name="leg_left_6_joint" type="revolute">
    <parent link="leg_left_5_link"/>
    <child link="leg_left_6_link"/>
    <origin rpy="0.0 0.0 0.0" xyz="0.00000 0.00000 0.00000"/>
    <axis xyz="1 0 0"/>
    <limit effort="100" lower="-0.5236" upper="0.5236" velocity="4.8"/>
    <dynamics damping="0.0" friction="0.0"/>
  </joint>
  <!-- from here is copy paste -->
  <link name="left_sole_link">
    <inertial>
      <mass value="0.01"/>
      <inertia ixx="0.0001" ixy="0" ixz="0" iyy="0.0001" iyz="0" izz="0.0001"/>
      <origin rpy="0 0 0" xyz="0 0 0"/>
    </inertial>
  </link>
  <joint name="leg_left_sole_fix_joint" type="fixed">
    <parent link="leg_left_6_link"/>
    <child link="left_sole_link"/>
    <origin rpy="0 0 0" xyz="0.00 0.00 -0.107"/>
    <axis xyz="1 0 0"/>
    <dynamics damping="0.0" friction="0.0"/>
  </joint>
  <transmission name="leg_left_1_trans">
    <type>transmission_interface/SimpleTransmission</type>
    <actuator name="leg_left_1_motor">
      <mechanicalReduction>1.0</mechanicalReduction>
    </actuator>
    <joint name="leg_left_1_joint">
      <hardwareInterface>hardware_interface/PositionJointInterface</hardwareInterface>
      <hardwareInterface>hardware_interface/EffortJointInterface</hardwareInterface>
    </joint>
  </transmission>
  <transmission name="leg_left_2_trans">
    <type>transmission_interface/SimpleTransmission</type>
    <actuator name="leg_left_2_motor">
      <mechanicalReduction>1.0</mechanicalReduction>
    </actuator>
    <joint name="leg_left_2_joint">
      <hardwareInterface>hardware_interface/PositionJointInterface</hardwareInterface>
      <hardwareInterface>hardware_interface/EffortJointInterface</hardwareInterface>
    </joint>
  </transmission>
  <transmission name="leg_left_3_trans">
    <type>transmission_interface/SimpleTransmission</type>
    <actuator name="leg_left_3_motor">
      <mechanicalReduction>1.0</mechanicalReduction>
    </actuator>
    <joint name="leg_left_3_joint">
      <hardwareInterface>hardware_interface/PositionJointInterface</hardwareInterface>
      <hardwareInterface>hardware_interface/EffortJointInterface</hardwareInterface>
    </joint>
  </transmission>
  <transmission name="leg_left_4_trans">
    <type>transmission_interface/SimpleTransmission</type>
    <actuator name="leg_left_4_motor">
      <mechanicalReduction>1.0</mechanicalReduction>
    </actuator>
    <joint name="leg_left_4_joint">
      <hardwareInterface>hardware_interface/PositionJointInterface</hardwareInterface>
      <hardwareInterface>hardware_interface/EffortJointInterface</hardwareInterface>
    </joint>
  </transmission>
  <transmission name="leg_left_5_trans">
    <type>transmission_interface/SimpleTransmission</type>
    <actuator name="leg_left_5_motor">
      <mechanicalReduction>1.0</mechanicalReduction>
    </actuator>
    <joint name="leg_left_5_joint">
      <hardwareInterface>hardware_interface/PositionJointInterface</hardwareInterface>
      <hardwareInterface>hardware_interface/EffortJointInterface</hardwareInterface>
    </joint>
  </transmission>
  <transmission name="leg_left_6_trans">
    <type>transmission_interface/SimpleTransmission</type>
    <actuator name="leg_left_6_motor">
      <mechanicalReduction>1.0</mechanicalReduction>
    </actuator>
    <joint name="leg_left_6_joint">
      <hardwareInterface>hardware_interface/PositionJointInterface</hardwareInterface>
      <hardwareInterface>hardware_interface/EffortJointInterface</hardwareInterface>
    </joint>
  </transmission>
  <gazebo reference="leg_left_1_link">
    <mu1>0.9</mu1>
    <mu2>0.9</mu2>
  </gazebo>
  <gazebo reference="leg_left_2_link">
    <mu1>0.9</mu1>
    <mu2>0.9</mu2>
  </gazebo>
  <gazebo reference="leg_left_3_link">
    <mu1>0.9</mu1>
    <mu2>0.9</mu2>
  </gazebo>
  <gazebo reference="leg_left_4_link">
    <mu1>0.9</mu1>
    <mu2>0.9</mu2>
  </gazebo>
  <gazebo reference="leg_left_5_link">
    <mu1>0.9</mu1>
    <mu2>0.9</mu2>
  </gazebo>
  <!-- contact model for foot surface -->
  <gazebo reference="leg_left_6_link">
    <kp>1000000.0</kp>
    <kd>100.0</kd>
    <mu1>1.0</mu1>
    <mu2>1.0</mu2>
    <fdir1>1 0 0</fdir1>
    <maxVel>1.0</maxVel>
    <minDepth>0.00</minDepth>
    <implicitSpringDamper>1</implicitSpringDamper>
  </gazebo>
  <gazebo reference="leg_left_1_joint">
    <implicitSpringDamper>1</implicitSpringDamper>
  </gazebo>
  <gazebo reference="leg_left_2_joint">
    <implicitSpringDamper>1</implicitSpringDamper>
  </gazebo>
  <gazebo reference="leg_left_3_joint">
    <implicitSpringDamper>1</implicitSpringDamper>
  </gazebo>
  <gazebo reference="leg_left_4_joint">
    <implicitSpringDamper>1</implicitSpringDamper>
  </gazebo>
  <gazebo reference="leg_left_5_joint">
    <implicitSpringDamper>1</implicitSpringDamper>
  </gazebo>
  <gazebo reference="leg_left_6_joint">
    <implicitSpringDamper>1</implicitSpringDamper>
    <provideFeedback>1</provideFeedback>
  </gazebo>
  <gazebo reference="leg_left_1_link">
    <material>Gazebo/FlatBlack</material>
  </gazebo>
  <gazebo reference="leg_left_2_link">
    <material>Gazebo/FlatBlack</material>
  </gazebo>
  <gazebo reference="leg_left_3_link">
    <material>Gazebo/FlatBlack</material>
  </gazebo>
  <gazebo reference="leg_left_4_link">
    <material>Gazebo/FlatBlack</material>
  </gazebo>
  <gazebo reference="leg_left_5_link">
    <material>Gazebo/White</material>
  </gazebo>
  <gazebo reference="leg_left_6_link">
    <material>Gazebo/White</material>
  </gazebo>
  <!-- Joint hip_z (mesh link) : child link hip_x -> parent link base_link -->
  <link name="leg_right_1_link">
    <inertial>
      <mass value="1.845591"/>
      <inertia ixx="0.00541533521" ixy="0.00015428714" ixz="0.00131612622" iyy="0.00848624936" iyz="1.906103e-05" izz="0.00474512541"/>
      <origin rpy="0 0 0" xyz="0.02247868 -0.00106736 0.03130665"/>
    </inertial>
    <visual>
      <origin rpy="0 0 0" xyz="0 0 0"/>
      <geometry>
        <mesh filename="package://talos_description/meshes/v2/hip_z_lo_res.stl" scale="1 -1 1"/>
      </geometry>
      <material name="DarkGrey"/>
    </visual>
    <collision>
      <origin rpy="0 0 0" xyz="0 0 0"/>
      <geometry>
        <mesh filename="package://talos_description/meshes/v2/hip_z_collision.stl" scale="1 -1 1"/>
      </geometry>
    </collision>
  </link>
  <joint name="leg_right_1_joint" type="revolute">
    <parent link="base_link"/>
    <child link="leg_right_1_link"/>
    <origin rpy="0.0 0.0 0.0" xyz="-0.02 -0.085 -0.27105"/>
    <axis xyz="0 0 1"/>
    <limit effort="100" lower="-1.57079632679" upper="0.349065850399" velocity="3.87"/>
    <dynamics damping="0.0" friction="0.0"/>
  </joint>
  <!-- Joint hip_x (mesh link) : child link hip_y -> parent link hip_z -->
  <link name="leg_right_2_link">
    <inertial>
      <mass value="1.490952"/>
      <inertia ixx="0.00497152259" ixy="0.0001311358" ixz="-4.86648e-06" iyy="0.00190550993" iyz="-4.585381e-05" izz="0.00474289754"/>
      <origin rpy="0 0 0" xyz="-0.00704703 -0.02592659 0.00273385"/>
    </inertial>
    <visual>
      <origin rpy="0  0  0" xyz="0 0 0.0"/>
      <geometry>
        <mesh filename="package://talos_description/meshes/v2/hip_x_lo_res.stl" scale="1 -1 1"/>
      </geometry>
      <material name="DarkGrey"/>
    </visual>
    <collision>
      <origin rpy="0  0  0" xyz="0 0 0.0"/>
      <geometry>
        <mesh filename="package://talos_description/meshes/v2/hip_x_collision.stl" scale="1 -1 1"/>
      </geometry>
    </collision>
  </link>
  <joint name="leg_right_2_joint" type="revolute">
    <parent link="leg_right_1_link"/>
    <child link="leg_right_2_link"/>
    <origin rpy="0.0 0.0 0.0" xyz="0.00000 0.00000 0.00000"/>
    <axis xyz="1 0 0"/>
    <limit effort="160" lower="-0.5236" upper="0.5236" velocity="5.8"/>
    <dynamics damping="0.0" friction="0.0"/>
  </joint>
  <!-- Joint hip_y (mesh link) : child link knee -> parent link hip_x -->
  <link name="leg_right_3_link">
    <inertial>
      <mass value="6.239871"/>
      <inertia ixx="0.15337403915" ixy="-0.00068913396" ixz="0.00168034366" iyy="0.13648139346" iyz="0.02187635445" izz="0.03001594885"/>
      <origin rpy="0 0 0" xyz="0.0058523 -0.0636967 -0.18339564"/>
    </inertial>
    <visual>
      <origin rpy="0 0 0" xyz="0 0 0"/>
      <geometry>
        <mesh filename="package://talos_description/meshes/v2/hip_y_lo_res.stl" scale="1 -1 1"/>
      </geometry>
      <material name="DarkGrey"/>
    </visual>
    <collision>
      <origin rpy="0 0 0" xyz="0 0 0"/>
      <geometry>
        <mesh filename="package://talos_description/meshes/v2/hip_y_collision.stl" scale="1 -1 1"/>
      </geometry>
    </collision>
  </link>
  <joint name="leg_right_3_joint" type="revolute">
    <parent link="leg_right_2_link"/>
    <child link="leg_right_3_link"/>
    <origin rpy="0.0 0.0 0.0" xyz="0.00000 0.00000 0.00000"/>
    <axis xyz="0 1 0"/>
    <limit effort="160" lower="-2.095" upper="0.7" velocity="5.8"/>
    <dynamics damping="0.0" friction="0.0"/>
  </joint>
  <!-- Joint knee (mesh link) : child link ankle_y -> parent link hip_y -->
  <link name="leg_right_4_link">
    <inertial>
      <mass value="3.759951"/>
      <inertia ixx="0.04287677484" ixy="-0.00043705397" ixz="0.00078292368" iyy="0.03598906971" iyz="-0.00037717694" izz="0.01364791564"/>
      <origin rpy="0 0 0" xyz="0.01317717 -0.02917508 -0.11594602"/>
    </inertial>
    <visual>
      <origin rpy="0 0 0" xyz="0 0 0"/>
      <geometry>
        <mesh filename="package://talos_description/meshes/v2/knee_lo_res.stl" scale="1 -1 1"/>
      </geometry>
      <material name="DarkGrey"/>
    </visual>
    <collision>
      <origin rpy="0 0 0" xyz="0 0 0"/>
      <geometry>
        <mesh filename="package://talos_description/meshes/v2/knee_collision.stl" scale="1 -1 1"/>
      </geometry>
    </collision>
  </link>
  <joint name="leg_right_4_joint" type="revolute">
    <parent link="leg_right_3_link"/>
    <child link="leg_right_4_link"/>
    <origin rpy="0.0 0.0 0.0" xyz="0.00000 0.00000 -0.38000"/>
    <axis xyz="0 1 0"/>
    <limit effort="400" lower="0" upper="2.618" velocity="7"/>
    <dynamics damping="0.0" friction="0.0"/>
  </joint>
  <!-- Joint ankle_y (mesh link) : child link ankle_x -> parent link knee -->
  <link name="leg_right_5_link">
    <inertial>
      <mass value="1.29096"/>
      <inertia ixx="0.01143430819" ixy="-0.00096978273" ixz="0.00039976581" iyy="0.00888974312" iyz="0.00277808667" izz="0.00506373875"/>
      <origin rpy="0 0 0" xyz="-0.01400838 -0.04180064 0.03820186"/>
    </inertial>
    <visual>
      <origin rpy="0 0 0" xyz="0 0 0.0"/>
      <geometry>
        <mesh filename="package://talos_description/meshes/v2/ankle_Y_lo_res.stl" scale="1 -1 1"/>
      </geometry>
      <material name="Grey"/>
    </visual>
    <collision>
      <origin rpy="0 0 0" xyz="0 0 0.0"/>
      <geometry>
        <mesh filename="package://talos_description/meshes/v2/ankle_Y_collision.stl" scale="1 -1 1"/>
      </geometry>
    </collision>
  </link>
  <joint name="leg_right_5_joint" type="revolute">
    <parent link="leg_right_4_link"/>
    <child link="leg_right_5_link"/>
    <origin rpy="0.0 0.0 0.0" xyz="0.00000 0.00000 -0.32500"/>
    <axis xyz="0 1 0"/>
    <limit effort="160" lower="-1.27" upper="0.68" velocity="5.8"/>
    <dynamics damping="0.0" friction="0.0"/>
  </joint>
  <!-- Joint ankle_x (mesh link) : child link None -> parent link ankle_y -->
  <link name="leg_right_6_link">
    <inertial>
      <mass value="1.597773"/>
      <inertia ixx="0.00439027267" ixy="6.743674e-05" ixz="0.00113816363" iyy="0.00743063029" iyz="-3.943143e-05" izz="0.00550906699"/>
      <origin rpy="0 0 0" xyz="-0.02034668 0.00051514 -0.05987428"/>
    </inertial>
    <visual>
      <origin rpy="0 0 0" xyz="0 0 0"/>
      <geometry>
        <mesh filename="package://talos_description/meshes/v2/ankle_X_lo_res.stl" scale="1 -1 1"/>
      </geometry>
      <material name="Grey"/>
    </visual>
    <collision>
      <origin rpy="0 0 0" xyz="0 0 0"/>
      <geometry>
        <mesh filename="package://talos_description/meshes/v2/ankle_X_collision.stl" scale="1 -1 1"/>
      </geometry>
    </collision>
  </link>
  <joint name="leg_right_6_joint" type="revolute">
    <parent link="leg_right_5_link"/>
    <child link="leg_right_6_link"/>
    <origin rpy="0.0 0.0 0.0" xyz="0.00000 0.00000 0.00000"/>
    <axis xyz="1 0 0"/>
    <limit effort="100" lower="-0.5236" upper="0.5236" velocity="4.8"/>
    <dynamics damping="0.0" friction="0.0"/>
  </joint>
  <!-- from here is copy paste -->
  <link name="right_sole_link">
    <inertial>
      <mass value="0.01"/>
      <inertia ixx="0.0001" ixy="0" ixz="0" iyy="0.0001" iyz="0" izz="0.0001"/>
      <origin rpy="0 0 0" xyz="0 0 0"/>
    </inertial>
  </link>
  <joint name="leg_right_sole_fix_joint" type="fixed">
    <parent link="leg_right_6_link"/>
    <child link="right_sole_link"/>
    <origin rpy="0 0 0" xyz="0.00 0.00 -0.107"/>
    <axis xyz="1 0 0"/>
    <dynamics damping="0.0" friction="0.0"/>
  </joint>
  <transmission name="leg_right_1_trans">
    <type>transmission_interface/SimpleTransmission</type>
    <actuator name="leg_right_1_motor">
      <mechanicalReduction>1.0</mechanicalReduction>
    </actuator>
    <joint name="leg_right_1_joint">
      <hardwareInterface>hardware_interface/PositionJointInterface</hardwareInterface>
      <hardwareInterface>hardware_interface/EffortJointInterface</hardwareInterface>
    </joint>
  </transmission>
  <transmission name="leg_right_2_trans">
    <type>transmission_interface/SimpleTransmission</type>
    <actuator name="leg_right_2_motor">
      <mechanicalReduction>1.0</mechanicalReduction>
    </actuator>
    <joint name="leg_right_2_joint">
      <hardwareInterface>hardware_interface/PositionJointInterface</hardwareInterface>
      <hardwareInterface>hardware_interface/EffortJointInterface</hardwareInterface>
    </joint>
  </transmission>
  <transmission name="leg_right_3_trans">
    <type>transmission_interface/SimpleTransmission</type>
    <actuator name="leg_right_3_motor">
      <mechanicalReduction>1.0</mechanicalReduction>
    </actuator>
    <joint name="leg_right_3_joint">
      <hardwareInterface>hardware_interface/PositionJointInterface</hardwareInterface>
      <hardwareInterface>hardware_interface/EffortJointInterface</hardwareInterface>
    </joint>
  </transmission>
  <transmission name="leg_right_4_trans">
    <type>transmission_interface/SimpleTransmission</type>
    <actuator name="leg_right_4_motor">
      <mechanicalReduction>1.0</mechanicalReduction>
    </actuator>
    <joint name="leg_right_4_joint">
      <hardwareInterface>hardware_interface/PositionJointInterface</hardwareInterface>
      <hardwareInterface>hardware_interface/EffortJointInterface</hardwareInterface>
    </joint>
  </transmission>
  <transmission name="leg_right_5_trans">
    <type>transmission_interface/SimpleTransmission</type>
    <actuator name="leg_right_5_motor">
      <mechanicalReduction>1.0</mechanicalReduction>
    </actuator>
    <joint name="leg_right_5_joint">
      <hardwareInterface>hardware_interface/PositionJointInterface</hardwareInterface>
      <hardwareInterface>hardware_interface/EffortJointInterface</hardwareInterface>
    </joint>
  </transmission>
  <transmission name="leg_right_6_trans">
    <type>transmission_interface/SimpleTransmission</type>
    <actuator name="leg_right_6_motor">
      <mechanicalReduction>1.0</mechanicalReduction>
    </actuator>
    <joint name="leg_right_6_joint">
      <hardwareInterface>hardware_interface/PositionJointInterface</hardwareInterface>
      <hardwareInterface>hardware_interface/EffortJointInterface</hardwareInterface>
    </joint>
  </transmission>
  <gazebo reference="leg_right_1_link">
    <mu1>0.9</mu1>
    <mu2>0.9</mu2>
  </gazebo>
  <gazebo reference="leg_right_2_link">
    <mu1>0.9</mu1>
    <mu2>0.9</mu2>
  </gazebo>
  <gazebo reference="leg_right_3_link">
    <mu1>0.9</mu1>
    <mu2>0.9</mu2>
  </gazebo>
  <gazebo reference="leg_right_4_link">
    <mu1>0.9</mu1>
    <mu2>0.9</mu2>
  </gazebo>
  <gazebo reference="leg_right_5_link">
    <mu1>0.9</mu1>
    <mu2>0.9</mu2>
  </gazebo>
  <!-- contact model for foot surface -->
  <gazebo reference="leg_right_6_link">
    <kp>1000000.0</kp>
    <kd>100.0</kd>
    <mu1>1.0</mu1>
    <mu2>1.0</mu2>
    <fdir1>1 0 0</fdir1>
    <maxVel>1.0</maxVel>
    <minDepth>0.00</minDepth>
    <implicitSpringDamper>1</implicitSpringDamper>
  </gazebo>
  <gazebo reference="leg_right_1_joint">
    <implicitSpringDamper>1</implicitSpringDamper>
  </gazebo>
  <gazebo reference="leg_right_2_joint">
    <implicitSpringDamper>1</implicitSpringDamper>
  </gazebo>
  <gazebo reference="leg_right_3_joint">
    <implicitSpringDamper>1</implicitSpringDamper>
  </gazebo>
  <gazebo reference="leg_right_4_joint">
    <implicitSpringDamper>1</implicitSpringDamper>
  </gazebo>
  <gazebo reference="leg_right_5_joint">
    <implicitSpringDamper>1</implicitSpringDamper>
  </gazebo>
  <gazebo reference="leg_right_6_joint">
    <implicitSpringDamper>1</implicitSpringDamper>
    <provideFeedback>1</provideFeedback>
  </gazebo>
  <gazebo reference="leg_right_1_link">
    <material>Gazebo/FlatBlack</material>
  </gazebo>
  <gazebo reference="leg_right_2_link">
    <material>Gazebo/FlatBlack</material>
  </gazebo>
  <gazebo reference="leg_right_3_link">
    <material>Gazebo/FlatBlack</material>
  </gazebo>
  <gazebo reference="leg_right_4_link">
    <material>Gazebo/FlatBlack</material>
  </gazebo>
  <gazebo reference="leg_right_5_link">
    <material>Gazebo/White</material>
  </gazebo>
  <gazebo reference="leg_right_6_link">
    <material>Gazebo/White</material>
  </gazebo>
  <gazebo>
    <plugin filename="libgazebo_ros_control.so" name="gazebo_ros_control">
      <ns/>
      <robotSimType>pal_hardware_gazebo/PalHardwareGazebo</robotSimType>
      <robotNamespace/>
      <controlPeriod>0.001</controlPeriod>
    </plugin>
  </gazebo>
  <gazebo>
    <plugin filename="libgazebo_world_odometry.so" name="gazebo_ros_odometry">
      <frameName>base_link</frameName>
      <topicName>floating_base_pose_simulated</topicName>
    </plugin>
  </gazebo>
  <gazebo>
    <plugin filename="libgazebo_ros_force.so" name="gazebo_ros_force">
      <bodyName>base_link</bodyName>
      <topicName>wrench</topicName>
    </plugin>
  </gazebo>
  <gazebo reference="imu_link">
    <!-- this is expected to be reparented to pelvis with appropriate offset
         when imu_link is reduced by fixed joint reduction -->
    <!-- todo: this is working with gazebo 1.4, need to write a unit test -->
    <sensor name="imu_sensor" type="imu">
      <always_on>1</always_on>
      <update_rate>1000.0</update_rate>
      <imu>
        <noise>
          <type>gaussian</type>
          <!-- Noise parameters from Boston Dynamics
               (http://gazebosim.org/wiki/Sensor_noise):
                 rates (rad/s): mean=0, stddev=2e-4
                 accels (m/s/s): mean=0, stddev=1.7e-2
                 rate bias (rad/s): 5e-6 - 1e-5
                 accel bias (m/s/s): 1e-1
               Experimentally, simulation provide rates with noise of
               about 1e-3 rad/s and accels with noise of about 1e-1 m/s/s.
               So we don't expect to see the noise unless number of inner iterations
               are increased.

               We will add bias.  In this model, bias is sampled once for rates
               and once for accels at startup; the sign (negative or positive)
               of each bias is then switched with equal probability.  Thereafter,
               the biases are fixed additive offsets.  We choose
               bias means and stddevs to produce biases close to the provided
               data. -->
          <!--
          <rate>
            <mean>0.0</mean>
            <stddev>2e-4</stddev>
            <bias_mean>0.0000075</bias_mean>
            <bias_stddev>0.0000008</bias_stddev>
          </rate>
          <accel>
            <mean>0.0</mean>
            <stddev>1.7e-2</stddev>
            <bias_mean>0.1</bias_mean>
            <bias_stddev>0.001</bias_stddev>
          </accel>
          -->
          <rate>
            <mean>0.0</mean>
            <stddev>0.0</stddev>
            <bias_mean>0.000000</bias_mean>
            <bias_stddev>0.0000008</bias_stddev>
          </rate>
          <accel>
            <mean>0.0</mean>
            <stddev>0.0</stddev>
            <bias_mean>0.0</bias_mean>
            <bias_stddev>0.000</bias_stddev>
          </accel>
        </noise>
      </imu>
    </sensor>
  </gazebo>
  <!-- define global properties -->
  <!-- <xacro:property name="M_PI" value="3.1415926535897931" /> -->
  <material name="Blue">
    <color rgba="0.0 0.0 0.8 1.0"/>
  </material>
  <material name="Green">
    <color rgba="0.0 0.8 0.0 1.0"/>
  </material>
  <material name="Grey">
    <color rgba="0.7 0.7 0.7 1.0"/>
  </material>
  <material name="LightGrey">
    <color rgba="0.9 0.9 0.9 1.0"/>
  </material>
  <material name="DarkGrey">
    <color rgba="0.2 0.2 0.2 1.0"/>
  </material>
  <material name="Red">
    <color rgba="0.8 0.0 0.0 1.0"/>
  </material>
  <material name="White">
    <color rgba="1.0 1.0 1.0 1.0"/>
  </material>
  <material name="Orange">
    <color rgba="1.0 0.5 0.0 1.0"/>
  </material>
</robot>

